log
test
log2019-01-23 13:48:53,913 - telegram.ext.dispatcher - ERROR - An uncaught error was raised while processing the update
Traceback (most recent call last):
  File "C:\Users\Administrator\AppData\Local\Programs\Python\Python35\lib\site-packages\telegram\ext\dispatcher.py", line 279, in process_update
    handler.handle_update(update, self)
  File "C:\Users\Administrator\AppData\Local\Programs\Python\Python35\lib\site-packages\telegram\ext\commandhandler.py", line 173, in handle_update
    return self.callback(dispatcher.bot, update, **optional_args)
  File "E:/Program/GITHUB/dominion/dominion.py", line 94, in start
    elif temp1 == 'Silver':
NameError: name 'temp1' is not defined
2019-01-27 18:34:16,212 - telegram.ext.updater - ERROR - Error while getting Updates: Conflict: terminated by other getUpdates request; make sure that only one bot instance is running (409)
2019-01-27 18:34:16,250 - __main__ - WARNING - Update "None" caused error "Conflict: terminated by other getUpdates request; make sure that only one bot instance is running (409)"
2019-01-27 18:34:21,603 - telegram.ext.updater - ERROR - Error while getting Updates: Conflict: terminated by other getUpdates request; make sure that only one bot instance is running (409)
2019-01-27 18:34:21,604 - __main__ - WARNING - Update "None" caused error "Conflict: terminated by other getUpdates request; make sure that only one bot instance is running (409)"
2019-01-27 18:34:27,949 - telegram.ext.updater - ERROR - Error while getting Updates: Conflict: terminated by other getUpdates request; make sure that only one bot instance is running (409)
2019-01-27 18:34:27,950 - __main__ - WARNING - Update "None" caused error "Conflict: terminated by other getUpdates request; make sure that only one bot instance is running (409)"
2019-01-27 18:34:33,248 - telegram.ext.updater - ERROR - Error while getting Updates: Conflict: terminated by other getUpdates request; make sure that only one bot instance is running (409)
2019-01-27 18:34:33,248 - __main__ - WARNING - Update "None" caused error "Conflict: terminated by other getUpdates request; make sure that only one bot instance is running (409)"
2019-01-27 18:34:40,971 - telegram.ext.updater - ERROR - Error while getting Updates: Conflict: terminated by other getUpdates request; make sure that only one bot instance is running (409)
2019-01-27 18:34:40,972 - __main__ - WARNING - Update "None" caused error "Conflict: terminated by other getUpdates request; make sure that only one bot instance is running (409)"
2019-01-27 18:34:50,384 - telegram.ext.updater - ERROR - Error while getting Updates: Conflict: terminated by other getUpdates request; make sure that only one bot instance is running (409)
2019-01-27 18:34:50,384 - __main__ - WARNING - Update "None" caused error "Conflict: terminated by other getUpdates request; make sure that only one bot instance is running (409)"
2019-01-27 18:35:02,346 - telegram.ext.updater - ERROR - Error while getting Updates: Conflict: terminated by other getUpdates request; make sure that only one bot instance is running (409)
2019-01-27 18:35:02,346 - __main__ - WARNING - Update "None" caused error "Conflict: terminated by other getUpdates request; make sure that only one bot instance is running (409)"
2019-01-27 23:20:57,525 - telegram.vendor.ptb_urllib3.urllib3.connectionpool - WARNING - Retrying (Retry(total=2, connect=None, read=None, redirect=None)) after connection broken by 'ConnectTimeoutError(<telegram.vendor.ptb_urllib3.urllib3.connection.VerifiedHTTPSConnection object at 0x02B49190>, 'Connection to api.telegram.org timed out. (connect timeout=5.0)')': /bot599551578:AAE709inuNhedfLCwIVKF9fWXJNJ-pqv5lg/getUpdates
2019-01-27 23:20:58,374 - telegram.vendor.ptb_urllib3.urllib3.connectionpool - WARNING - Retrying (Retry(total=1, connect=None, read=None, redirect=None)) after connection broken by 'NewConnectionError('<telegram.vendor.ptb_urllib3.urllib3.connection.VerifiedHTTPSConnection object at 0x02B496F0>: Failed to establish a new connection: [Errno 11004] getaddrinfo failed')': /bot599551578:AAE709inuNhedfLCwIVKF9fWXJNJ-pqv5lg/getUpdates
2019-01-27 23:20:58,375 - telegram.vendor.ptb_urllib3.urllib3.connectionpool - WARNING - Retrying (Retry(total=0, connect=None, read=None, redirect=None)) after connection broken by 'NewConnectionError('<telegram.vendor.ptb_urllib3.urllib3.connection.VerifiedHTTPSConnection object at 0x02B49290>: Failed to establish a new connection: [Errno 11004] getaddrinfo failed')': /bot599551578:AAE709inuNhedfLCwIVKF9fWXJNJ-pqv5lg/getUpdates
2019-01-27 23:20:58,376 - telegram.ext.updater - ERROR - Error while getting Updates: urllib3 HTTPError HTTPSConnectionPool(host='api.telegram.org', port=443): Max retries exceeded with url: /bot599551578:AAE709inuNhedfLCwIVKF9fWXJNJ-pqv5lg/getUpdates (Caused by NewConnectionError('<telegram.vendor.ptb_urllib3.urllib3.connection.VerifiedHTTPSConnection object at 0x02B49830>: Failed to establish a new connection: [Errno 11004] getaddrinfo failed'))
2019-01-27 23:20:58,376 - __main__ - WARNING - Update "None" caused error "urllib3 HTTPError HTTPSConnectionPool(host='api.telegram.org', port=443): Max retries exceeded with url: /bot599551578:AAE709inuNhedfLCwIVKF9fWXJNJ-pqv5lg/getUpdates (Caused by NewConnectionError('<telegram.vendor.ptb_urllib3.urllib3.connection.VerifiedHTTPSConnection object at 0x02B49830>: Failed to establish a new connection: [Errno 11004] getaddrinfo failed'))"
2019-01-27 23:20:59,391 - telegram.vendor.ptb_urllib3.urllib3.connectionpool - WARNING - Retrying (Retry(total=2, connect=None, read=None, redirect=None)) after connection broken by 'NewConnectionError('<telegram.vendor.ptb_urllib3.urllib3.connection.VerifiedHTTPSConnection object at 0x02B49390>: Failed to establish a new connection: [Errno 11004] getaddrinfo failed')': /bot599551578:AAE709inuNhedfLCwIVKF9fWXJNJ-pqv5lg/getUpdates
2019-01-27 23:20:59,392 - telegram.vendor.ptb_urllib3.urllib3.connectionpool - WARNING - Retrying (Retry(total=1, connect=None, read=None, redirect=None)) after connection broken by 'NewConnectionError('<telegram.vendor.ptb_urllib3.urllib3.connection.VerifiedHTTPSConnection object at 0x02B9DEB0>: Failed to establish a new connection: [Errno 11004] getaddrinfo failed')': /bot599551578:AAE709inuNhedfLCwIVKF9fWXJNJ-pqv5lg/getUpdates
2019-01-27 23:20:59,392 - telegram.vendor.ptb_urllib3.urllib3.connectionpool - WARNING - Retrying (Retry(total=0, connect=None, read=None, redirect=None)) after connection broken by 'NewConnectionError('<telegram.vendor.ptb_urllib3.urllib3.connection.VerifiedHTTPSConnection object at 0x02B9DF70>: Failed to establish a new connection: [Errno 11004] getaddrinfo failed')': /bot599551578:AAE709inuNhedfLCwIVKF9fWXJNJ-pqv5lg/getUpdates
2019-01-27 23:20:59,393 - telegram.ext.updater - ERROR - Error while getting Updates: urllib3 HTTPError HTTPSConnectionPool(host='api.telegram.org', port=443): Max retries exceeded with url: /bot599551578:AAE709inuNhedfLCwIVKF9fWXJNJ-pqv5lg/getUpdates (Caused by NewConnectionError('<telegram.vendor.ptb_urllib3.urllib3.connection.VerifiedHTTPSConnection object at 0x02B9DBD0>: Failed to establish a new connection: [Errno 11004] getaddrinfo failed'))
2019-01-27 23:20:59,393 - __main__ - WARNING - Update "None" caused error "urllib3 HTTPError HTTPSConnectionPool(host='api.telegram.org', port=443): Max retries exceeded with url: /bot599551578:AAE709inuNhedfLCwIVKF9fWXJNJ-pqv5lg/getUpdates (Caused by NewConnectionError('<telegram.vendor.ptb_urllib3.urllib3.connection.VerifiedHTTPSConnection object at 0x02B9DBD0>: Failed to establish a new connection: [Errno 11004] getaddrinfo failed'))"
2019-01-27 23:21:00,893 - telegram.vendor.ptb_urllib3.urllib3.connectionpool - WARNING - Retrying (Retry(total=2, connect=None, read=None, redirect=None)) after connection broken by 'NewConnectionError('<telegram.vendor.ptb_urllib3.urllib3.connection.VerifiedHTTPSConnection object at 0x02B9DD70>: Failed to establish a new connection: [Errno 11004] getaddrinfo failed')': /bot599551578:AAE709inuNhedfLCwIVKF9fWXJNJ-pqv5lg/getUpdates
2019-01-27 23:21:00,894 - telegram.vendor.ptb_urllib3.urllib3.connectionpool - WARNING - Retrying (Retry(total=1, connect=None, read=None, redirect=None)) after connection broken by 'NewConnectionError('<telegram.vendor.ptb_urllib3.urllib3.connection.VerifiedHTTPSConnection object at 0x02B9DBB0>: Failed to establish a new connection: [Errno 11004] getaddrinfo failed')': /bot599551578:AAE709inuNhedfLCwIVKF9fWXJNJ-pqv5lg/getUpdates
2019-01-27 23:21:00,895 - telegram.vendor.ptb_urllib3.urllib3.connectionpool - WARNING - Retrying (Retry(total=0, connect=None, read=None, redirect=None)) after connection broken by 'NewConnectionError('<telegram.vendor.ptb_urllib3.urllib3.connection.VerifiedHTTPSConnection object at 0x02B9DED0>: Failed to establish a new connection: [Errno 11004] getaddrinfo failed')': /bot599551578:AAE709inuNhedfLCwIVKF9fWXJNJ-pqv5lg/getUpdates
2019-01-27 23:21:00,895 - telegram.ext.updater - ERROR - Error while getting Updates: urllib3 HTTPError HTTPSConnectionPool(host='api.telegram.org', port=443): Max retries exceeded with url: /bot599551578:AAE709inuNhedfLCwIVKF9fWXJNJ-pqv5lg/getUpdates (Caused by NewConnectionError('<telegram.vendor.ptb_urllib3.urllib3.connection.VerifiedHTTPSConnection object at 0x02B9D9D0>: Failed to establish a new connection: [Errno 11004] getaddrinfo failed'))
2019-01-27 23:21:00,895 - __main__ - WARNING - Update "None" caused error "urllib3 HTTPError HTTPSConnectionPool(host='api.telegram.org', port=443): Max retries exceeded with url: /bot599551578:AAE709inuNhedfLCwIVKF9fWXJNJ-pqv5lg/getUpdates (Caused by NewConnectionError('<telegram.vendor.ptb_urllib3.urllib3.connection.VerifiedHTTPSConnection object at 0x02B9D9D0>: Failed to establish a new connection: [Errno 11004] getaddrinfo failed'))"
2019-01-27 23:21:03,183 - telegram.vendor.ptb_urllib3.urllib3.connectionpool - WARNING - Retrying (Retry(total=2, connect=None, read=None, redirect=None)) after connection broken by 'NewConnectionError('<telegram.vendor.ptb_urllib3.urllib3.connection.VerifiedHTTPSConnection object at 0x02B9DA70>: Failed to establish a new connection: [Errno 11004] getaddrinfo failed')': /bot599551578:AAE709inuNhedfLCwIVKF9fWXJNJ-pqv5lg/getUpdates
2019-01-27 23:21:03,216 - telegram.vendor.ptb_urllib3.urllib3.connectionpool - WARNING - Retrying (Retry(total=1, connect=None, read=None, redirect=None)) after connection broken by 'NewConnectionError('<telegram.vendor.ptb_urllib3.urllib3.connection.VerifiedHTTPSConnection object at 0x02B9D470>: Failed to establish a new connection: [Errno 11004] getaddrinfo failed')': /bot599551578:AAE709inuNhedfLCwIVKF9fWXJNJ-pqv5lg/getUpdates
2019-01-27 23:21:03,239 - telegram.vendor.ptb_urllib3.urllib3.connectionpool - WARNING - Retrying (Retry(total=0, connect=None, read=None, redirect=None)) after connection broken by 'NewConnectionError('<telegram.vendor.ptb_urllib3.urllib3.connection.VerifiedHTTPSConnection object at 0x02B9D830>: Failed to establish a new connection: [Errno 11004] getaddrinfo failed')': /bot599551578:AAE709inuNhedfLCwIVKF9fWXJNJ-pqv5lg/getUpdates
2019-01-27 23:21:03,265 - telegram.ext.updater - ERROR - Error while getting Updates: urllib3 HTTPError HTTPSConnectionPool(host='api.telegram.org', port=443): Max retries exceeded with url: /bot599551578:AAE709inuNhedfLCwIVKF9fWXJNJ-pqv5lg/getUpdates (Caused by NewConnectionError('<telegram.vendor.ptb_urllib3.urllib3.connection.VerifiedHTTPSConnection object at 0x02B9D6D0>: Failed to establish a new connection: [Errno 11004] getaddrinfo failed'))
2019-01-27 23:21:03,265 - __main__ - WARNING - Update "None" caused error "urllib3 HTTPError HTTPSConnectionPool(host='api.telegram.org', port=443): Max retries exceeded with url: /bot599551578:AAE709inuNhedfLCwIVKF9fWXJNJ-pqv5lg/getUpdates (Caused by NewConnectionError('<telegram.vendor.ptb_urllib3.urllib3.connection.VerifiedHTTPSConnection object at 0x02B9D6D0>: Failed to establish a new connection: [Errno 11004] getaddrinfo failed'))"
2019-01-27 23:21:06,716 - telegram.vendor.ptb_urllib3.urllib3.connectionpool - WARNING - Retrying (Retry(total=2, connect=None, read=None, redirect=None)) after connection broken by 'NewConnectionError('<telegram.vendor.ptb_urllib3.urllib3.connection.VerifiedHTTPSConnection object at 0x02B9D490>: Failed to establish a new connection: [Errno 11004] getaddrinfo failed')': /bot599551578:AAE709inuNhedfLCwIVKF9fWXJNJ-pqv5lg/getUpdates
2019-01-27 23:21:06,725 - telegram.vendor.ptb_urllib3.urllib3.connectionpool - WARNING - Retrying (Retry(total=1, connect=None, read=None, redirect=None)) after connection broken by 'NewConnectionError('<telegram.vendor.ptb_urllib3.urllib3.connection.VerifiedHTTPSConnection object at 0x02B7F430>: Failed to establish a new connection: [Errno 11004] getaddrinfo failed')': /bot599551578:AAE709inuNhedfLCwIVKF9fWXJNJ-pqv5lg/getUpdates
2019-01-27 23:21:06,778 - telegram.vendor.ptb_urllib3.urllib3.connectionpool - WARNING - Retrying (Retry(total=0, connect=None, read=None, redirect=None)) after connection broken by 'NewConnectionError('<telegram.vendor.ptb_urllib3.urllib3.connection.VerifiedHTTPSConnection object at 0x02B7F4D0>: Failed to establish a new connection: [Errno 11004] getaddrinfo failed')': /bot599551578:AAE709inuNhedfLCwIVKF9fWXJNJ-pqv5lg/getUpdates
2019-01-27 23:21:06,780 - telegram.ext.updater - ERROR - Error while getting Updates: urllib3 HTTPError HTTPSConnectionPool(host='api.telegram.org', port=443): Max retries exceeded with url: /bot599551578:AAE709inuNhedfLCwIVKF9fWXJNJ-pqv5lg/getUpdates (Caused by NewConnectionError('<telegram.vendor.ptb_urllib3.urllib3.connection.VerifiedHTTPSConnection object at 0x02B7F650>: Failed to establish a new connection: [Errno 11004] getaddrinfo failed'))
2019-01-27 23:21:06,780 - __main__ - WARNING - Update "None" caused error "urllib3 HTTPError HTTPSConnectionPool(host='api.telegram.org', port=443): Max retries exceeded with url: /bot599551578:AAE709inuNhedfLCwIVKF9fWXJNJ-pqv5lg/getUpdates (Caused by NewConnectionError('<telegram.vendor.ptb_urllib3.urllib3.connection.VerifiedHTTPSConnection object at 0x02B7F650>: Failed to establish a new connection: [Errno 11004] getaddrinfo failed'))"
2019-01-27 23:21:17,041 - telegram.ext.updater - ERROR - Error while getting Updates: Conflict: terminated by other getUpdates request; make sure that only one bot instance is running (409)
2019-01-27 23:21:17,041 - __main__ - WARNING - Update "None" caused error "Conflict: terminated by other getUpdates request; make sure that only one bot instance is running (409)"
2019-01-27 23:21:28,929 - telegram.ext.updater - ERROR - Error while getting Updates: Conflict: terminated by other getUpdates request; make sure that only one bot instance is running (409)
2019-01-27 23:21:28,949 - __main__ - WARNING - Update "None" caused error "Conflict: terminated by other getUpdates request; make sure that only one bot instance is running (409)"
